2025-05-05 14:04:19,805 WARNING Register payload: {'name': 'Olzhas Saduakhas', 'phone': '77026929624', 'email': 'olzhas.taukent@gmail.com', 'password': 'Taukent2004$', 'password_confirmation': 'Taukent2004$', 'role': 'CUSTOMER'}
2025-05-05 14:05:21,710 WARNING Register payload: {'name': 'Olzhas Saduakhas', 'phone': '77026929624', 'email': 'olzhas.taukent@gmail.com', 'password': 'Taukent2004$', 'password_confirmation': 'Taukent2004$', 'role': 'CUSTOMER'}
2025-05-05 14:06:46,681 WARNING Register payload: {'name': 'Olzhas Saduakhas', 'phone': '77026929624', 'email': 'olzhas.taukent@gmail.com', 'password': 'Taukent2004$', 'password_confirmation': 'Taukent2004$', 'role': 'CUSTOMER'}
2025-05-05 14:07:10,670 WARNING Register payload: {'name': 'Olzhas Saduakhas', 'phone': '77026929624', 'email': 'olzhas.taukent@gmail.com', 'password': 'Taukent2004$', 'password_confirmation': 'Taukent2004$', 'role': 'CUSTOMER'}
2025-05-05 14:09:25,256 WARNING Register payload: {'name': 'Olzhas Saduakhas', 'phone': '77026929624', 'email': 'olzhas.taukent@gmail.com', 'password': 'Taukent2004$', 'password_confirmation': 'Taukent2004$', 'role': 'CUSTOMER'}
2025-05-05 14:09:25,299 WARNING Serializer errors: {'email': [ErrorDetail(string=' with this email already exists.', code='unique')]}
2025-05-05 14:09:56,155 WARNING Register payload: {'name': 'Olzhas Saduakhas', 'phone': '77026929624', 'email': 'o.taukent@gmail.com', 'password': 'Taukent2004$', 'password_confirmation': 'Taukent2004$', 'role': 'CUSTOMER'}
2025-05-05 14:09:56,168 WARNING Serializer errors: {'phone': [ErrorDetail(string='User with this phone number already exists.', code='invalid')]}
2025-05-05 14:10:03,039 WARNING Register payload: {'name': 'Olzhas Saduakhas', 'phone': '77026929620', 'email': 'o.taukent@gmail.com', 'password': 'Taukent2004$', 'password_confirmation': 'Taukent2004$', 'role': 'CUSTOMER'}
2025-05-05 14:18:46,248 INFO PaymentIntent created
2025-05-05 14:18:53,836 INFO User requested payment history
2025-05-05 14:18:53,865 INFO User requested payment history
2025-05-05 14:18:54,941 INFO User requested payment history
2025-05-05 14:18:54,965 INFO User requested payment history
2025-05-05 14:19:16,796 INFO User requested payment history
2025-05-05 14:19:16,820 INFO User requested payment history
2025-05-05 14:19:17,401 INFO User requested payment history
2025-05-05 14:19:17,422 INFO User requested payment history
2025-05-05 14:19:45,831 INFO User requested payment history
2025-05-05 14:19:45,859 INFO User requested payment history
2025-05-05 14:19:58,017 INFO User requested payment history
2025-05-05 14:19:58,039 INFO User requested payment history
2025-05-05 14:22:44,325 INFO PaymentIntent created
2025-05-05 14:27:13,305 ERROR Invalid HTTP_HOST header: 'host.docker.internal:8000'. You may need to add 'host.docker.internal' to ALLOWED_HOSTS.
Traceback (most recent call last):
  File "/usr/local/lib/python3.11/site-packages/asgiref/sync.py", line 518, in thread_handler
    raise exc_info[1]
  File "/usr/local/lib/python3.11/site-packages/django/core/handlers/exception.py", line 42, in inner
    response = await get_response(request)
               ^^^^^^^^^^^^^^^^^^^^^^^^^^^
  File "/usr/local/lib/python3.11/site-packages/django/utils/deprecation.py", line 132, in __acall__
    response = await sync_to_async(
               ^^^^^^^^^^^^^^^^^^^^
  File "/usr/local/lib/python3.11/site-packages/asgiref/sync.py", line 468, in __call__
    ret = await asyncio.shield(exec_coro)
          ^^^^^^^^^^^^^^^^^^^^^^^^^^^^^^^
  File "/usr/local/lib/python3.11/concurrent/futures/thread.py", line 58, in run
    result = self.fn(*self.args, **self.kwargs)
             ^^^^^^^^^^^^^^^^^^^^^^^^^^^^^^^^^^
  File "/usr/local/lib/python3.11/site-packages/asgiref/sync.py", line 522, in thread_handler
    return func(*args, **kwargs)
           ^^^^^^^^^^^^^^^^^^^^^
  File "/usr/local/lib/python3.11/site-packages/django/middleware/common.py", line 48, in process_request
    host = request.get_host()
           ^^^^^^^^^^^^^^^^^^
  File "/usr/local/lib/python3.11/site-packages/django/http/request.py", line 186, in get_host
    raise DisallowedHost(msg)
django.core.exceptions.DisallowedHost: Invalid HTTP_HOST header: 'host.docker.internal:8000'. You may need to add 'host.docker.internal' to ALLOWED_HOSTS.
2025-05-05 14:27:13,353 ERROR Invalid HTTP_HOST header: 'host.docker.internal:8000'. You may need to add 'host.docker.internal' to ALLOWED_HOSTS.
Traceback (most recent call last):
  File "/usr/local/lib/python3.11/site-packages/asgiref/sync.py", line 518, in thread_handler
    raise exc_info[1]
  File "/usr/local/lib/python3.11/site-packages/django/core/handlers/exception.py", line 42, in inner
    response = await get_response(request)
               ^^^^^^^^^^^^^^^^^^^^^^^^^^^
  File "/usr/local/lib/python3.11/site-packages/django/utils/deprecation.py", line 132, in __acall__
    response = await sync_to_async(
               ^^^^^^^^^^^^^^^^^^^^
  File "/usr/local/lib/python3.11/site-packages/asgiref/sync.py", line 468, in __call__
    ret = await asyncio.shield(exec_coro)
          ^^^^^^^^^^^^^^^^^^^^^^^^^^^^^^^
  File "/usr/local/lib/python3.11/concurrent/futures/thread.py", line 58, in run
    result = self.fn(*self.args, **self.kwargs)
             ^^^^^^^^^^^^^^^^^^^^^^^^^^^^^^^^^^
  File "/usr/local/lib/python3.11/site-packages/asgiref/sync.py", line 522, in thread_handler
    return func(*args, **kwargs)
           ^^^^^^^^^^^^^^^^^^^^^
  File "/usr/local/lib/python3.11/site-packages/django/middleware/common.py", line 48, in process_request
    host = request.get_host()
           ^^^^^^^^^^^^^^^^^^
  File "/usr/local/lib/python3.11/site-packages/django/http/request.py", line 186, in get_host
    raise DisallowedHost(msg)
django.core.exceptions.DisallowedHost: Invalid HTTP_HOST header: 'host.docker.internal:8000'. You may need to add 'host.docker.internal' to ALLOWED_HOSTS.
2025-05-05 14:27:13,651 ERROR Invalid HTTP_HOST header: 'host.docker.internal:8000'. You may need to add 'host.docker.internal' to ALLOWED_HOSTS.
Traceback (most recent call last):
  File "/usr/local/lib/python3.11/site-packages/asgiref/sync.py", line 518, in thread_handler
    raise exc_info[1]
  File "/usr/local/lib/python3.11/site-packages/django/core/handlers/exception.py", line 42, in inner
    response = await get_response(request)
               ^^^^^^^^^^^^^^^^^^^^^^^^^^^
  File "/usr/local/lib/python3.11/site-packages/django/utils/deprecation.py", line 132, in __acall__
    response = await sync_to_async(
               ^^^^^^^^^^^^^^^^^^^^
  File "/usr/local/lib/python3.11/site-packages/asgiref/sync.py", line 468, in __call__
    ret = await asyncio.shield(exec_coro)
          ^^^^^^^^^^^^^^^^^^^^^^^^^^^^^^^
  File "/usr/local/lib/python3.11/concurrent/futures/thread.py", line 58, in run
    result = self.fn(*self.args, **self.kwargs)
             ^^^^^^^^^^^^^^^^^^^^^^^^^^^^^^^^^^
  File "/usr/local/lib/python3.11/site-packages/asgiref/sync.py", line 522, in thread_handler
    return func(*args, **kwargs)
           ^^^^^^^^^^^^^^^^^^^^^
  File "/usr/local/lib/python3.11/site-packages/django/middleware/common.py", line 48, in process_request
    host = request.get_host()
           ^^^^^^^^^^^^^^^^^^
  File "/usr/local/lib/python3.11/site-packages/django/http/request.py", line 186, in get_host
    raise DisallowedHost(msg)
django.core.exceptions.DisallowedHost: Invalid HTTP_HOST header: 'host.docker.internal:8000'. You may need to add 'host.docker.internal' to ALLOWED_HOSTS.
2025-05-05 14:27:15,815 ERROR Invalid HTTP_HOST header: 'host.docker.internal:8000'. You may need to add 'host.docker.internal' to ALLOWED_HOSTS.
Traceback (most recent call last):
  File "/usr/local/lib/python3.11/site-packages/asgiref/sync.py", line 518, in thread_handler
    raise exc_info[1]
  File "/usr/local/lib/python3.11/site-packages/django/core/handlers/exception.py", line 42, in inner
    response = await get_response(request)
               ^^^^^^^^^^^^^^^^^^^^^^^^^^^
  File "/usr/local/lib/python3.11/site-packages/django/utils/deprecation.py", line 132, in __acall__
    response = await sync_to_async(
               ^^^^^^^^^^^^^^^^^^^^
  File "/usr/local/lib/python3.11/site-packages/asgiref/sync.py", line 468, in __call__
    ret = await asyncio.shield(exec_coro)
          ^^^^^^^^^^^^^^^^^^^^^^^^^^^^^^^
  File "/usr/local/lib/python3.11/concurrent/futures/thread.py", line 58, in run
    result = self.fn(*self.args, **self.kwargs)
             ^^^^^^^^^^^^^^^^^^^^^^^^^^^^^^^^^^
  File "/usr/local/lib/python3.11/site-packages/asgiref/sync.py", line 522, in thread_handler
    return func(*args, **kwargs)
           ^^^^^^^^^^^^^^^^^^^^^
  File "/usr/local/lib/python3.11/site-packages/django/middleware/common.py", line 48, in process_request
    host = request.get_host()
           ^^^^^^^^^^^^^^^^^^
  File "/usr/local/lib/python3.11/site-packages/django/http/request.py", line 186, in get_host
    raise DisallowedHost(msg)
django.core.exceptions.DisallowedHost: Invalid HTTP_HOST header: 'host.docker.internal:8000'. You may need to add 'host.docker.internal' to ALLOWED_HOSTS.
2025-05-05 14:41:45,250 INFO PaymentIntent created
2025-05-05 14:41:45,366 ERROR Invalid HTTP_HOST header: 'web:8000'. You may need to add 'web' to ALLOWED_HOSTS.
Traceback (most recent call last):
  File "/usr/local/lib/python3.11/site-packages/asgiref/sync.py", line 518, in thread_handler
    raise exc_info[1]
  File "/usr/local/lib/python3.11/site-packages/django/core/handlers/exception.py", line 42, in inner
    response = await get_response(request)
               ^^^^^^^^^^^^^^^^^^^^^^^^^^^
  File "/usr/local/lib/python3.11/site-packages/django/utils/deprecation.py", line 132, in __acall__
    response = await sync_to_async(
               ^^^^^^^^^^^^^^^^^^^^
  File "/usr/local/lib/python3.11/site-packages/asgiref/sync.py", line 468, in __call__
    ret = await asyncio.shield(exec_coro)
          ^^^^^^^^^^^^^^^^^^^^^^^^^^^^^^^
  File "/usr/local/lib/python3.11/concurrent/futures/thread.py", line 58, in run
    result = self.fn(*self.args, **self.kwargs)
             ^^^^^^^^^^^^^^^^^^^^^^^^^^^^^^^^^^
  File "/usr/local/lib/python3.11/site-packages/asgiref/sync.py", line 522, in thread_handler
    return func(*args, **kwargs)
           ^^^^^^^^^^^^^^^^^^^^^
  File "/usr/local/lib/python3.11/site-packages/django/middleware/common.py", line 48, in process_request
    host = request.get_host()
           ^^^^^^^^^^^^^^^^^^
  File "/usr/local/lib/python3.11/site-packages/django/http/request.py", line 186, in get_host
    raise DisallowedHost(msg)
django.core.exceptions.DisallowedHost: Invalid HTTP_HOST header: 'web:8000'. You may need to add 'web' to ALLOWED_HOSTS.
2025-05-05 14:41:47,333 ERROR Invalid HTTP_HOST header: 'web:8000'. You may need to add 'web' to ALLOWED_HOSTS.
Traceback (most recent call last):
  File "/usr/local/lib/python3.11/site-packages/asgiref/sync.py", line 518, in thread_handler
    raise exc_info[1]
  File "/usr/local/lib/python3.11/site-packages/django/core/handlers/exception.py", line 42, in inner
    response = await get_response(request)
               ^^^^^^^^^^^^^^^^^^^^^^^^^^^
  File "/usr/local/lib/python3.11/site-packages/django/utils/deprecation.py", line 132, in __acall__
    response = await sync_to_async(
               ^^^^^^^^^^^^^^^^^^^^
  File "/usr/local/lib/python3.11/site-packages/asgiref/sync.py", line 468, in __call__
    ret = await asyncio.shield(exec_coro)
          ^^^^^^^^^^^^^^^^^^^^^^^^^^^^^^^
  File "/usr/local/lib/python3.11/concurrent/futures/thread.py", line 58, in run
    result = self.fn(*self.args, **self.kwargs)
             ^^^^^^^^^^^^^^^^^^^^^^^^^^^^^^^^^^
  File "/usr/local/lib/python3.11/site-packages/asgiref/sync.py", line 522, in thread_handler
    return func(*args, **kwargs)
           ^^^^^^^^^^^^^^^^^^^^^
  File "/usr/local/lib/python3.11/site-packages/django/middleware/common.py", line 48, in process_request
    host = request.get_host()
           ^^^^^^^^^^^^^^^^^^
  File "/usr/local/lib/python3.11/site-packages/django/http/request.py", line 186, in get_host
    raise DisallowedHost(msg)
django.core.exceptions.DisallowedHost: Invalid HTTP_HOST header: 'web:8000'. You may need to add 'web' to ALLOWED_HOSTS.
2025-05-05 14:41:47,433 ERROR Invalid HTTP_HOST header: 'web:8000'. You may need to add 'web' to ALLOWED_HOSTS.
Traceback (most recent call last):
  File "/usr/local/lib/python3.11/site-packages/asgiref/sync.py", line 518, in thread_handler
    raise exc_info[1]
  File "/usr/local/lib/python3.11/site-packages/django/core/handlers/exception.py", line 42, in inner
    response = await get_response(request)
               ^^^^^^^^^^^^^^^^^^^^^^^^^^^
  File "/usr/local/lib/python3.11/site-packages/django/utils/deprecation.py", line 132, in __acall__
    response = await sync_to_async(
               ^^^^^^^^^^^^^^^^^^^^
  File "/usr/local/lib/python3.11/site-packages/asgiref/sync.py", line 468, in __call__
    ret = await asyncio.shield(exec_coro)
          ^^^^^^^^^^^^^^^^^^^^^^^^^^^^^^^
  File "/usr/local/lib/python3.11/concurrent/futures/thread.py", line 58, in run
    result = self.fn(*self.args, **self.kwargs)
             ^^^^^^^^^^^^^^^^^^^^^^^^^^^^^^^^^^
  File "/usr/local/lib/python3.11/site-packages/asgiref/sync.py", line 522, in thread_handler
    return func(*args, **kwargs)
           ^^^^^^^^^^^^^^^^^^^^^
  File "/usr/local/lib/python3.11/site-packages/django/middleware/common.py", line 48, in process_request
    host = request.get_host()
           ^^^^^^^^^^^^^^^^^^
  File "/usr/local/lib/python3.11/site-packages/django/http/request.py", line 186, in get_host
    raise DisallowedHost(msg)
django.core.exceptions.DisallowedHost: Invalid HTTP_HOST header: 'web:8000'. You may need to add 'web' to ALLOWED_HOSTS.
2025-05-05 14:41:49,922 ERROR Invalid HTTP_HOST header: 'web:8000'. You may need to add 'web' to ALLOWED_HOSTS.
Traceback (most recent call last):
  File "/usr/local/lib/python3.11/site-packages/asgiref/sync.py", line 518, in thread_handler
    raise exc_info[1]
  File "/usr/local/lib/python3.11/site-packages/django/core/handlers/exception.py", line 42, in inner
    response = await get_response(request)
               ^^^^^^^^^^^^^^^^^^^^^^^^^^^
  File "/usr/local/lib/python3.11/site-packages/django/utils/deprecation.py", line 132, in __acall__
    response = await sync_to_async(
               ^^^^^^^^^^^^^^^^^^^^
  File "/usr/local/lib/python3.11/site-packages/asgiref/sync.py", line 468, in __call__
    ret = await asyncio.shield(exec_coro)
          ^^^^^^^^^^^^^^^^^^^^^^^^^^^^^^^
  File "/usr/local/lib/python3.11/concurrent/futures/thread.py", line 58, in run
    result = self.fn(*self.args, **self.kwargs)
             ^^^^^^^^^^^^^^^^^^^^^^^^^^^^^^^^^^
  File "/usr/local/lib/python3.11/site-packages/asgiref/sync.py", line 522, in thread_handler
    return func(*args, **kwargs)
           ^^^^^^^^^^^^^^^^^^^^^
  File "/usr/local/lib/python3.11/site-packages/django/middleware/common.py", line 48, in process_request
    host = request.get_host()
           ^^^^^^^^^^^^^^^^^^
  File "/usr/local/lib/python3.11/site-packages/django/http/request.py", line 186, in get_host
    raise DisallowedHost(msg)
django.core.exceptions.DisallowedHost: Invalid HTTP_HOST header: 'web:8000'. You may need to add 'web' to ALLOWED_HOSTS.
2025-05-05 14:48:24,250 INFO PaymentIntent created
2025-05-05 14:48:24,410 ERROR HTTP POST /api/payments/webhook/ 500 [0.04, 172.18.0.5:47142]
2025-05-05 14:48:27,005 ERROR HTTP POST /api/payments/webhook/ 500 [0.13, 172.18.0.5:47142]
2025-05-05 14:48:27,032 ERROR HTTP POST /api/payments/webhook/ 500 [0.03, 172.18.0.5:49044]
2025-05-05 14:48:29,486 ERROR HTTP POST /api/payments/webhook/ 500 [0.03, 172.18.0.5:49044]
2025-05-05 14:51:34,297 INFO PaymentIntent created
2025-05-05 14:51:34,402 WARNING Received Stripe webhook
2025-05-05 14:51:35,434 WARNING Received Stripe webhook
2025-05-05 14:51:35,452 INFO Payment succeeded and user balance updated
2025-05-05 14:51:36,647 WARNING Received Stripe webhook
2025-05-05 14:51:37,994 WARNING Received Stripe webhook
2025-05-05 14:51:41,157 INFO User requested payment history
2025-05-05 14:51:41,178 INFO User requested payment history
2025-05-05 14:52:15,853 INFO User requested payment history
2025-05-05 14:52:15,871 INFO User requested payment history
